======================================================================
ERROR: test_verification_phase (__main__.TestSPARKProtocol.test_verification_phase)
Test Verification Phase.
----------------------------------------------------------------------
Traceback (most recent call last):
  File "/home/novie/Code/Secure-CAN_Attestation-Protocol/Secure-CAN_Attestation-Protocol/src/test_crypto.py", line 107, in test_verification_phase
    result = self.protocol.verification_phase(signature, self.message, self.edge)
             ^^^^^^^^^^^^^^^^^^^^^^^^^^^^^^^^^^^^^^^^^^^^^^^^^^^^^^^^^^^^^^^^^^^^
  File "/home/novie/Code/Secure-CAN_Attestation-Protocol/Secure-CAN_Attestation-Protocol/src/protocol.py", line 123, in verification_phase
    result = self.internal_verifier.verify_signature(
             ^^^^^^^^^^^^^^^^^^^^^^^^^^^^^^^^^^^^^^^^
  File "/home/novie/Code/Secure-CAN_Attestation-Protocol/Secure-CAN_Attestation-Protocol/src/entities.py", line 124, in verify_signature
    G_k_tilde = [CryptoUtils.hash_to_G1(GROUP.serialize(pk)).__class__(G0_tilde) for pk in G_k]
                 ^^^^^^^^^^^^^^^^^^^^^^^^^^^^^^^^^^^^^^^^^^^^^^^^^^^^^^^^^^^^^^^
SystemError: <class 'pairing.Element'> returned NULL without setting an exception

======================================================================
FAIL: test_tracing_phase (__main__.TestSPARKProtocol.test_tracing_phase)
Test Tracing Phase.
----------------------------------------------------------------------
Traceback (most recent call last):
  File "/home/novie/Code/Secure-CAN_Attestation-Protocol/Secure-CAN_Attestation-Protocol/src/test_crypto.py", line 117, in test_tracing_phase
    self.assertEqual(traced_pk, self.edge.tpm.public_key)
AssertionError: None != [2474434908210391515179452458271606058389[111 chars]7298]

----------------------------------------------------------------------
Ran 9 tests in 2.085s

FAILED (failures=1, errors=1)